<?xml version="1.0" encoding="UTF-8" standalone="yes"?>
<sdf version="1.5">
    <model name="upperBodyXO_v1">
        <joint name="ra1_sho_abad" type="revolute">
            <axis>
                <dynamics>
                    <damping>0.1</damping>
                    <friction>0</friction>
                </dynamics>
                <limit>
                    <effort>100</effort>
                    <lower>-0.17453</lower>
                    <upper>2.0944</upper>
                    <velocity>12</velocity>
                </limit>
                <xyz>-0.64279 -0.76604 0</xyz>
            </axis>
            <child>r_ushou</child>
            <parent>pelvis</parent>
        </joint>
        <joint name="ra2_sho_flex" type="revolute">
            <axis>
                <dynamics>
                    <damping>0.1</damping>
                    <friction>0</friction>
                </dynamics>
                <limit>
                    <effort>100</effort>
                    <lower>-0.47647</lower>
                    <upper>2.0944</upper>
                    <velocity>12</velocity>
                </limit>
                <xyz>0 0 -1</xyz>
            </axis>
            <child>r_lshou</child>
            <parent>r_ushou</parent>
        </joint>
        <joint name="ra3_hum_rota" type="revolute">
            <axis>
                <dynamics>
                    <damping>0.1</damping>
                    <friction>0</friction>
                </dynamics>
                <limit>
                    <effort>100</effort>
                    <lower>-1.3963</lower>
                    <upper>0.87266</upper>
                    <velocity>12</velocity>
                </limit>
                <xyz>-0.99619 -0.087156 0</xyz>
            </axis>
            <child>r_uarm</child>
            <parent>r_lshou</parent>
        </joint>
        <joint name="ra4_elb_flex" type="revolute">
            <axis>
                <dynamics>
                    <damping>0.1</damping>
                    <friction>0</friction>
                </dynamics>
                <limit>
                    <effort>100</effort>
                    <lower>0</lower>
                    <upper>2.6704</upper>
                    <velocity>12</velocity>
                </limit>
                <xyz>0 0 -1</xyz>
            </axis>
            <child>r_larm</child>
            <parent>r_uarm</parent>
        </joint>
        <joint name="ra5_wri_rota" type="revolute">
            <axis>
                <dynamics>
                    <damping>0.1</damping>
                    <friction>0</friction>
                </dynamics>
                <limit>
                    <effort>100</effort>
                    <lower>-1.5708</lower>
                    <upper>1.5708</upper>
                    <velocity>10</velocity>
                </limit>
                <xyz>-1 -9.7145e-17 0</xyz>
            </axis>
            <child>r_hand</child>
            <parent>r_larm</parent>
        </joint>
        <joint name="la1_sho_abad" type="revolute">
            <axis>
                <dynamics>
                    <damping>0.1</damping>
                    <friction>0</friction>
                </dynamics>
                <limit>
                    <effort>100</effort>
                    <lower>-0.17453</lower>
                    <upper>2.0944</upper>
                    <velocity>12</velocity>
                </limit>
                <xyz>0.64279 0.76604 0</xyz>
            </axis>
            <child>l_ushou</child>
            <parent>pelvis</parent>
        </joint>
        <joint name="la2_sho_flex" type="revolute">
            <axis>
                <dynamics>
                    <damping>0.1</damping>
                    <friction>0</friction>
                </dynamics>
                <limit>
                    <effort>100</effort>
                    <lower>-0.47647</lower>
                    <upper>2.0944</upper>
                    <velocity>12</velocity>
                </limit>
                <xyz>0 0 -1</xyz>
            </axis>
            <child>l_lshou</child>
            <parent>l_ushou</parent>
        </joint>
        <joint name="la3_hum_rota" type="revolute">
            <axis>
                <dynamics>
                    <damping>0.1</damping>
                    <friction>0</friction>
                </dynamics>
                <limit>
                    <effort>100</effort>
                    <lower>-1.3963</lower>
                    <upper>0.87266</upper>
                    <velocity>12</velocity>
                </limit>
                <xyz>0.99619 0.087156 0</xyz>
            </axis>
            <child>l_uarm</child>
            <parent>l_lshou</parent>
        </joint>
        <joint name="la4_elb_flex" type="revolute">
            <axis>
                <dynamics>
                    <damping>0.1</damping>
                    <friction>0</friction>
                </dynamics>
                <limit>
                    <effort>100</effort>
                    <lower>0</lower>
                    <upper>2.6704</upper>
                    <velocity>12</velocity>
                </limit>
                <xyz>0 0 -1</xyz>
            </axis>
            <child>l_larm</child>
            <parent>l_uarm</parent>
        </joint>
        <joint name="la5_wri_rota" type="revolute">
            <axis>
                <dynamics>
                    <damping>0.1</damping>
                    <friction>0</friction>
                </dynamics>
                <limit>
                    <effort>100</effort>
                    <lower>-1.5708</lower>
                    <upper>1.5708</upper>
                    <velocity>10</velocity>
                </limit>
                <xyz>1 9.7145e-17 0</xyz>
            </axis>
            <child>l_hand</child>
            <parent>l_larm</parent>
        </joint>
        <joint name="ft3_l_hand" type="revolute">
            <axis>
                <dynamics>
                    <damping>0.1</damping>
                    <friction>0</friction>
                </dynamics>
                <limit>
                    <effort>200</effort>
                    <lower>-0.005</lower>
                    <upper>0.005</upper>
                    <velocity>3</velocity>
                </limit>
                <xyz>9.7145e-17 -1 0</xyz>
            </axis>
            <child>l_hand_FT</child>
            <parent>l_hand</parent>
        </joint>
        <joint name="ft4_r_hand" type="revolute">
            <axis>
                <dynamics>
                    <damping>0.1</damping>
                    <friction>0</friction>
                </dynamics>
                <limit>
                    <effort>200</effort>
                    <lower>-0.005</lower>
                    <upper>0.005</upper>
                    <velocity>4</velocity>
                </limit>
                <xyz>-9.7145e-17 1 0</xyz>
            </axis>
            <child>r_hand_FT</child>
            <parent>r_hand</parent>
        </joint>
        <link name="pelvis">
            <inertial>
                <inertia>
                    <ixx>0.086831</ixx>
                    <ixy>-9.8e-05</ixy>
                    <ixz>-1.4e-06</ixz>
                    <iyy>0.12768</iyy>
                    <iyz>-0.019368</iyz>
                    <izz>0.12709</izz>
                </inertia>
                <mass>12.8142</mass>
                <pose>0.00115 0.02425 0.00012 0 -1.5708 0</pose>
            </inertial>
            <pose>0 0 0 0 0 0</pose>
            <sensor name="imu_sensor_at_pelvis_frame" type="imu">
                <imu>
                    <noise>
                        <accel>
                            <bias_mean>0.1</bias_mean>
                            <bias_stddev>0.001</bias_stddev>
                            <mean>0</mean>
                            <stddev>0.017</stddev>
                        </accel>
                        <rate>
                            <bias_mean>7.5e-06</bias_mean>
                            <bias_stddev>8e-07</bias_stddev>
                            <mean>0</mean>
                            <stddev>0.0002</stddev>
                        </rate>
                        <type>gaussian</type>
                    </noise>
                </imu>
                <pose>0 0 0 0 0 0</pose>
                <update_rate>1000</update_rate>
            </sensor>
            <visual name="pelvis_visual_box">
                <geometry>
                    <box>
                        <size>0.7 0.1 0.07</size>
                    </box>
                </geometry>
                <material>
                    <ambient>1 1 1 1</ambient>
                    <diffuse>0.5 0.5 0.5 1</diffuse>
                    <emissive>0 0 0 1</emissive>
                    <specular>1 1 1 1</specular>
                </material>
                <transparency>0.2</transparency>
                <pose>0 -0.02 0 0.7854 0 0</pose>
            </visual>
            <visual name="pelvis_visual_box">
                <geometry>
                    <cylinder>
                        <length>1.2</length>
                        <radius>0.1905</radius>
                    </cylinder>
                </geometry>
                <material>
                    <ambient>1 1 1 1</ambient>
                    <diffuse>0.5 0.5 0.5 1</diffuse>
                    <emissive>0 0 0 1</emissive>
                    <specular>1 1 1 1</specular>
                </material>
                <transparency>0.2</transparency>
                <pose>0 0 0.6 0 0 0</pose>
            </visual>
        </link>
        <link name="r_ushou">
            <inertial>
                <inertia>
                    <ixx>0.0017929</ixx>
                    <ixy>0.0017929</ixy>
                    <ixz>0.0046508</ixz>
                    <iyy>0.034874</iyy>
                    <iyz>0.0073972</iyz>
                    <izz>0.012524</izz>
                </inertia>
                <mass>4.8909</mass>
                <pose>0.0164 0.0039 -0.19416 0 0 0</pose>
            </inertial>
            <pose>0.036922 -0.0097288 -0.31433 0 1.5708 -2.2689</pose>
            <visual name="r_ushou_visual_jointCylinder">
                <geometry>
                    <cylinder>
                        <length>0.04</length>
                        <radius>0.015</radius>
                    </cylinder>
                </geometry>
                <material>
                    <ambient>0 0 0 1</ambient>
                    <diffuse>0.5 0.5 0.5 1</diffuse>
                    <emissive>0 0 0 1</emissive>
                    <specular>0 0 0 1</specular>
                </material>
                <pose>0 0 0 0 0 0</pose>
            </visual>
            <visual name="r_ushou_visual_box">
                <geometry>
                    <box>
                        <size>0.06 0.1 0.3302</size>
                    </box>
                </geometry>
                <material>
                    <ambient>1 1 1 1</ambient>
                    <diffuse>0.5 0.5 0.5 1</diffuse>
                    <emissive>0 0 0 1</emissive>
                    <specular>1 1 1 1</specular>
                </material>
                <transparency>0.2</transparency>
                <pose>0 0 -0.16307 0 0 0</pose>
            </visual>
        </link>
        <link name="r_lshou">
            <inertial>
                <inertia>
                    <ixx>0.0042548</ixx>
                    <ixy>0.0002492</ixy>
                    <ixz>-0.0002769</ixz>
                    <iyy>0.0076126</iyy>
                    <iyz>-5.2e-05</iyz>
                    <izz>0.007705</izz>
                </inertia>
                <mass>3.2262</mass>
                <pose>0.11093 0.01825 0.02571 0 0 0</pose>
            </inertial>
            <pose>0.21581 0.28249 -0.30798 3.1416 0 -3.0543</pose>
            <visual name="r_lshou_visual_jointCylinder">
                <geometry>
                    <cylinder>
                        <length>0.04</length>
                        <radius>0.015</radius>
                    </cylinder>
                </geometry>
                <material>
                    <ambient>0 0 0 1</ambient>
                    <diffuse>0.5 0.5 0.5 1</diffuse>
                    <emissive>0 0 0 1</emissive>
                    <specular>0 0 0 1</specular>
                </material>
                <pose>0 0 0 0 0 0</pose>
            </visual>
            <visual name="r_lshou_visual_box">
                <geometry>
                    <box>
                        <size>0.15494 0.1 0.06</size>
                    </box>
                </geometry>
                <material>
                    <ambient>1 1 1 1</ambient>
                    <diffuse>0.5 0.5 0.5 1</diffuse>
                    <emissive>0 0 0 1</emissive>
                    <specular>1 1 1 1</specular>
                </material>
                <transparency>0.2</transparency>
                <pose>0.0772 0.024536 0.024638 0 0 -0.087266</pose>
            </visual>
        </link>
        <link name="r_uarm">
            <inertial>
                <inertia>
                    <ixx>0.019109</ixx>
                    <ixy>0.0001927</ixy>
                    <ixz>-0.0025684</ixz>
                    <iyy>0.018812</iyy>
                    <iyz>-0.0002236</iyz>
                    <izz>0.011074</izz>
                </inertia>
                <mass>4.8829</mass>
                <pose>-0.00114 -0.00151 0.11122 0 0 0</pose>
            </inertial>
            <pose>0.061406 0.29874 -0.33889 0 -1.5708 -0.087266</pose>
            <visual name="r_uarm_visual_jointCylinder">
                <geometry>
                    <cylinder>
                        <length>0.04</length>
                        <radius>0.015</radius>
                    </cylinder>
                </geometry>
                <material>
                    <ambient>0 0 0 1</ambient>
                    <diffuse>0.5 0.5 0.5 1</diffuse>
                    <emissive>0 0 0 1</emissive>
                    <specular>0 0 0 1</specular>
                </material>
                <pose>0 0 0 0 0 0</pose>
            </visual>
            <visual name="r_uarm_visual_box">
                <geometry>
                    <box>
                        <size>0.06 0.1 0.18796</size>
                    </box>
                </geometry>
                <material>
                    <ambient>1 1 1 1</ambient>
                    <diffuse>0.5 0.5 0.5 1</diffuse>
                    <emissive>0 0 0 1</emissive>
                    <specular>1 1 1 1</specular>
                </material>
                <transparency>0.2</transparency>
                <pose>0 -0.0081788 0.09398 0 0 -0.087266</pose>
            </visual>
        </link>
        <link name="r_larm">
            <inertial>
                <inertia>
                    <ixx>0.0004628</ixx>
                    <ixy>0.0009098</ixy>
                    <ixz>-0.0004177</ixz>
                    <iyy>0.010386</iyy>
                    <iyz>-1.28e-05</iyz>
                    <izz>0.010507</izz>
                </inertia>
                <mass>0.69113</mass>
                <pose>0.11918 -0.02395 -0.03337 0 0 0</pose>
            </inertial>
            <pose>-0.12707 0.28225 -0.34524 3.1416 0 -3.1416</pose>
            <visual name="r_larm_visual_jointCylinder">
                <geometry>
                    <cylinder>
                        <length>0.04</length>
                        <radius>0.015</radius>
                    </cylinder>
                </geometry>
                <material>
                    <ambient>0 0 0 1</ambient>
                    <diffuse>0.5 0.5 0.5 1</diffuse>
                    <emissive>0 0 0 1</emissive>
                    <specular>0 0 0 1</specular>
                </material>
                <pose>0 0 0 0 0 0</pose>
            </visual>
            <visual name="r_larm_visual_box">
                <geometry>
                    <box>
                        <size>0.3429 0.05 0.05</size>
                    </box>
                </geometry>
                <material>
                    <ambient>1 1 1 1</ambient>
                    <diffuse>0.5 0.5 0.5 1</diffuse>
                    <emissive>0 0 0 1</emissive>
                    <specular>1 1 1 1</specular>
                </material>
                <transparency>0.2</transparency>
                <pose>0.17145 0.003048 -0.03683 0 0 0</pose>
            </visual>
        </link>
        <link name="r_hand">
            <inertial>
                <inertia>
                    <ixx>0.016224</ixx>
                    <ixy>0.000437</ixy>
                    <ixz>0.0051128</ixz>
                    <iyy>0.039465</iyy>
                    <iyz>-0.0003224</iyz>
                    <izz>0.034758</izz>
                </inertia>
                <mass>3.2281</mass>
                <pose>0.07931 0.00146 0.0648 0 0 0</pose>
            </inertial>
            <pose>-0.46997 0.27615 -0.30226 0 -1.5708 -9.7145e-17</pose>
            <visual name="r_hand_visual_jointCylinder">
                <geometry>
                    <cylinder>
                        <length>0.04</length>
                        <radius>0.015</radius>
                    </cylinder>
                </geometry>
                <material>
                    <ambient>0 0 0 1</ambient>
                    <diffuse>0.5 0.5 0.5 1</diffuse>
                    <emissive>0 0 0 1</emissive>
                    <specular>0 0 0 1</specular>
                </material>
                <pose>0 0 0 0 0 0</pose>
            </visual>
            <visual name="r_hand_visual_box">
                <geometry>
                    <box>
                        <size>0.1524 0.1 0.06</size>
                    </box>
                </geometry>
                <material>
                    <ambient>1 1 1 1</ambient>
                    <diffuse>0.5 0.5 0.5 1</diffuse>
                    <emissive>0 0 0 1</emissive>
                    <specular>1 1 1 1</specular>
                </material>
                <transparency>0.2</transparency>
                <pose>0.0762 0 0.083388 0 0 0</pose>
            </visual>
        </link>
        <link name="l_ushou">
            <inertial>
                <inertia>
                    <ixx>0.036159</ixx>
                    <ixy>0.0018219</ixy>
                    <ixz>-0.0046394</ixz>
                    <iyy>0.034888</iyy>
                    <iyz>-0.0074231</iyz>
                    <izz>0.012539</izz>
                </inertia>
                <mass>4.8909</mass>
                <pose>0.01647 0.00381 0.19425 0 0 0</pose>
            </inertial>
            <pose>0.036922 -0.0097288 0.31432 0 -1.5708 2.2689</pose>
            <visual name="l_ushou_visual_jointCylinder">
                <geometry>
                    <cylinder>
                        <length>0.04</length>
                        <radius>0.015</radius>
                    </cylinder>
                </geometry>
                <material>
                    <ambient>0 0 0 1</ambient>
                    <diffuse>0.5 0.5 0.5 1</diffuse>
                    <emissive>0 0 0 1</emissive>
                    <specular>0 0 0 1</specular>
                </material>
                <pose>0 0 0 0 0 0</pose>
            </visual>
            <visual name="l_ushou_visual_box">
                <geometry>
                    <box>
                        <size>0.06 0.1 0.3302</size>
                    </box>
                </geometry>
                <material>
                    <ambient>1 1 1 1</ambient>
                    <diffuse>0.5 0.5 0.5 1</diffuse>
                    <emissive>0 0 0 1</emissive>
                    <specular>1 1 1 1</specular>
                </material>
                <transparency>0.2</transparency>
                <pose>0 0 0.16307 0 0 0</pose>
            </visual>
        </link>
        <link name="l_lshou">
            <inertial>
                <inertia>
                    <ixx>0.0042649</ixx>
                    <ixy>0.0002646</ixy>
                    <ixz>0.0002986</ixz>
                    <iyy>0.0076452</iyy>
                    <iyz>5.18e-05</iyz>
                    <izz>0.0077414</izz>
                </inertia>
                <mass>3.231</mass>
                <pose>0.11087 0.0182 -0.02557 0 0 0</pose>
            </inertial>
            <pose>0.21581 0.28249 0.30797 3.1416 0 -3.0543</pose>
            <visual name="l_lshou_visual_jointCylinder">
                <geometry>
                    <cylinder>
                        <length>0.04</length>
                        <radius>0.015</radius>
                    </cylinder>
                </geometry>
                <material>
                    <ambient>0 0 0 1</ambient>
                    <diffuse>0.5 0.5 0.5 1</diffuse>
                    <emissive>0 0 0 1</emissive>
                    <specular>0 0 0 1</specular>
                </material>
                <pose>0 0 0 0 0 0</pose>
            </visual>
            <visual name="l_lshou_visual_box">
                <geometry>
                    <box>
                        <size>0.15494 0.1 0.06</size>
                    </box>
                </geometry>
                <material>
                    <ambient>1 1 1 1</ambient>
                    <diffuse>0.5 0.5 0.5 1</diffuse>
                    <emissive>0 0 0 1</emissive>
                    <specular>1 1 1 1</specular>
                </material>
                <transparency>0.2</transparency>
                <pose>0.0772 0.024536 -0.024638 0 0 -0.087266</pose>
            </visual>
        </link>
        <link name="l_uarm">
            <inertial>
                <inertia>
                    <ixx>0.019132</ixx>
                    <ixy>0.0001585</ixy>
                    <ixz>0.0025749</ixz>
                    <iyy>0.018815</iyy>
                    <iyz>0.0002531</iyz>
                    <izz>0.011079</izz>
                </inertia>
                <mass>4.8803</mass>
                <pose>-0.00112 -0.00157 -0.11125 0 0 0</pose>
            </inertial>
            <pose>0.061403 0.29873 0.33889 0 1.5708 0.087266</pose>
            <visual name="l_uarm_visual_jointCylinder">
                <geometry>
                    <cylinder>
                        <length>0.04</length>
                        <radius>0.015</radius>
                    </cylinder>
                </geometry>
                <material>
                    <ambient>0 0 0 1</ambient>
                    <diffuse>0.5 0.5 0.5 1</diffuse>
                    <emissive>0 0 0 1</emissive>
                    <specular>0 0 0 1</specular>
                </material>
                <pose>0 0 0 0 0 0</pose>
            </visual>
            <visual name="l_uarm_visual_box">
                <geometry>
                    <box>
                        <size>0.06 0.1 0.18796</size>
                    </box>
                </geometry>
                <material>
                    <ambient>1 1 1 1</ambient>
                    <diffuse>0.5 0.5 0.5 1</diffuse>
                    <emissive>0 0 0 1</emissive>
                    <specular>1 1 1 1</specular>
                </material>
                <transparency>0.2</transparency>
                <pose>0 -0.0081788 -0.09398 0 0 -0.087266</pose>
            </visual>
        </link>
        <link name="l_larm">
            <inertial>
                <inertia>
                    <ixx>0.0004628</ixx>
                    <ixy>0.0009098</ixy>
                    <ixz>0.0004177</ixz>
                    <iyy>0.010386</iyy>
                    <iyz>1.28e-05</iyz>
                    <izz>0.010507</izz>
                </inertia>
                <mass>0.69113</mass>
                <pose>0.11918 -0.02395 0.0337 0 0 0</pose>
            </inertial>
            <pose>-0.12708 0.28224 0.34524 3.1416 0 -3.1416</pose>
            <visual name="l_larm_visual_jointCylinder">
                <geometry>
                    <cylinder>
                        <length>0.04</length>
                        <radius>0.015</radius>
                    </cylinder>
                </geometry>
                <material>
                    <ambient>0 0 0 1</ambient>
                    <diffuse>0.5 0.5 0.5 1</diffuse>
                    <emissive>0 0 0 1</emissive>
                    <specular>0 0 0 1</specular>
                </material>
                <pose>0 0 0 0 0 0</pose>
            </visual>
            <visual name="l_larm_visual_box">
                <geometry>
                    <box>
                        <size>0.3429 0.05 0.05</size>
                    </box>
                </geometry>
                <material>
                    <ambient>1 1 1 1</ambient>
                    <diffuse>0.5 0.5 0.5 1</diffuse>
                    <emissive>0 0 0 1</emissive>
                    <specular>1 1 1 1</specular>
                </material>
                <transparency>0.2</transparency>
                <pose>0.17145 0.003048 0.03683 0 0 0</pose>
            </visual>
        </link>
        <link name="l_hand">
            <inertial>
                <inertia>
                    <ixx>0.015967</ixx>
                    <ixy>0.0002098</ixy>
                    <ixz>-0.0057656</ixz>
                    <iyy>0.039945</iyy>
                    <iyz>0.0002799</iyz>
                    <izz>0.034993</izz>
                </inertia>
                <mass>3.231</mass>
                <pose>0.07931 0.00146 -0.0648 0 0 0</pose>
            </inertial>
            <pose>-0.46998 0.27615 0.30226 0 1.5708 9.7145e-17</pose>
            <visual name="l_hand_visual_jointCylinder">
                <geometry>
                    <cylinder>
                        <length>0.04</length>
                        <radius>0.015</radius>
                    </cylinder>
                </geometry>
                <material>
                    <ambient>0 0 0 1</ambient>
                    <diffuse>0.5 0.5 0.5 1</diffuse>
                    <emissive>0 0 0 1</emissive>
                    <specular>0 0 0 1</specular>
                </material>
                <pose>0 0 0 0 0 0</pose>
            </visual>
            <visual name="l_hand_visual_box">
                <geometry>
                    <box>
                        <size>0.1524 0.1 0.06</size>
                    </box>
                </geometry>
                <material>
                    <ambient>1 1 1 1</ambient>
                    <diffuse>0.5 0.5 0.5 1</diffuse>
                    <emissive>0 0 0 1</emissive>
                    <specular>1 1 1 1</specular>
                </material>
                <transparency>0.2</transparency>
                <pose>0.0762 0 -0.083388 0 0 0</pose>
            </visual>
        </link>
        <link name="l_hand_FT">
            <inertial>
                <inertia>
                    <ixx>0.001</ixx>
                    <ixy>0</ixy>
                    <ixz>0</ixz>
                    <iyy>0.001</iyy>
                    <iyz>0</iyz>
                    <izz>0.001</izz>
                </inertia>
                <mass>0.001</mass>
                <pose>0 0 0 0 0 1.7453e-05</pose>
            </inertial>
            <pose>-0.55338 0.27615 0.30226 -1.5708 0 -3.1416</pose>
        </link>
        <link name="r_hand_FT">
            <inertial>
                <inertia>
                    <ixx>0.001</ixx>
                    <ixy>0</ixy>
                    <ixz>0</ixz>
                    <iyy>0.001</iyy>
                    <iyz>0</iyz>
                    <izz>0.001</izz>
                </inertia>
                <mass>0.001</mass>
                <pose>0 0 0 0 0 1.7453e-05</pose>
            </inertial>
            <pose>-0.38657 0.27615 -0.30226 -1.5708 0 9.7145e-17</pose>
        </link>
        <pose>0 0 0 0 -1.5708 0</pose>
    </model>
</sdf>
